Workbook

Sheet 対応管理表
A1: 備品トラブル対応台帳 | E1: ="未完了 "&COUNTIFS($B$3:$B$1002,"<>完了",$B$3:$B$1002,"<>")&" 件"&" │ 期限超過 "&COUNTIF($D$3:$D$1002,"超過")&" 件"&" │ 期限間近 "&COUNTIF($D$3:$D$1002,"間近")&" 件"&" │ 担当未定 "&COUNTIFS($B$3:$B$1002,"<>完了",$B$3:$B$1002,"<>",$G$3:$G$1002,"")&" 件" | N1: ="本日 "&TEXT(TODAY(),"yyyy/mm/dd")&" │ 次に使う管理No. "&TEXT(YEAR(TODAY()),"0")&"-"&TEXT(SUMPRODUCT(MAX((LEFT($A$3:$A$302,4)=TEXT(YEAR(TODAY()),"0"))*IFERROR(VALUE(RIGHT($A$3:$A$302,3)),0)))+1,"000")
A2: 管理No. | B2: 対応状況 | C2: 対象物（品名） | D2: 期限判定 | E2: 対応期限 | F2: 優先度 | G2: 対応担当者 | H2: 区分 | I2: 受付日 | J2: 経過日数 | K2: 完了日 | L2: 発生日 | M2: 発生場所 | N2: 報告者（部署・氏名） | O2: 資産番号・管理番号 | P2: 状況・詳細 | Q2: 対応内容・経過（最新を上に） | R2: 警察届出 | S2: 費用（円） | T2: 備考
A3: 2026-001 | B3: 対応中 | C3: ノートPC（営業部貸与） | D3: =IF(OR(E3="",B3="完了"),"",IF(TODAY()>E3,"超過",IF(TODAY()+3>=E3,"間近",""))) | E3: 46283 | F3: 高 | G3: 総務 山田 | H3: 破損 | I3: 46273 | J3: =IF(I3="","",IF(K3<>"",K3-I3,TODAY()-I3)) | L3: 46272 | M3: 3F 営業部フロア | N3: 営業部 田中 | O3: PC-0123 | P3: 移動中に落下し、液晶画面が割れて表示できない。データは無事。 | Q3: 9/14 修理発注。納品予定が遅れているため再確認 9/11 見積受領（45,000円）、上長承認 9/8 メーカーへ修理見積依頼 | R3: 不要 | S3: 45000 | T3: ※記入例（削除してOK）
A4: 2026-002 | B4: 未対応 | C4: 社用自転車 | D4: =IF(OR(E4="",B4="完了"),"",IF(TODAY()>E4,"超過",IF(TODAY()+3>=E4,"間近",""))) | E4: 46287 | F4: 中 | G4: 総務 佐藤 | H4: 盗難 | I4: 46283 | J4: =IF(I4="","",IF(K4<>"",K4-I4,TODAY()-I4)) | L4: 46282 | M4: 本社 駐輪場 | N4: 総務部 鈴木 | O4: BK-002 | P4: 夜間に施錠して駐輪、翌朝出社時になくなっていた。防犯カメラ確認中。 | Q4: 9/18 上長へ報告済。警察への被害届は未提出。 | R4: 未 | T4: ※記入例（削除してOK）
A5: 2026-003 | B5: 完了 | C5: 複合機（2F コピーコーナー） | D5: =IF(OR(E5="",B5="完了"),"",IF(TODAY()>E5,"超過",IF(TODAY()+3>=E5,"間近",""))) | E5: 46267 | F5: 中 | G5: 総務 山田 | H5: 故障 | I5: 46260 | J5: =IF(I5="","",IF(K5<>"",K5-I5,TODAY()-I5)) | K5: 46262 | L5: 46260 | M5: 2F コピーコーナー | N5: 経理部 高橋 | O5: MFP-02 | P5: 紙詰まりが頻発し、エラー表示が消えない。 | Q5: 8/28 訪問修理（給紙ローラー交換）、動作確認済 8/26 保守業者へ連絡 | R5: 不要 | S5: 0 | T5: ※記入例（削除してOK）保守契約内のため費用0円
D6: =IF(OR(E6="",B6="完了"),"",IF(TODAY()>E6,"超過",IF(TODAY()+3>=E6,"間近",""))) | J6: =IF(I6="","",IF(K6<>"",K6-I6,TODAY()-I6))
D7: =IF(OR(E7="",B7="完了"),"",IF(TODAY()>E7,"超過",IF(TODAY()+3>=E7,"間近",""))) | J7: =IF(I7="","",IF(K7<>"",K7-I7,TODAY()-I7))
D8: =IF(OR(E8="",B8="完了"),"",IF(TODAY()>E8,"超過",IF(TODAY()+3>=E8,"間近",""))) | J8: =IF(I8="","",IF(K8<>"",K8-I8,TODAY()-I8))
D9: =IF(OR(E9="",B9="完了"),"",IF(TODAY()>E9,"超過",IF(TODAY()+3>=E9,"間近",""))) | J9: =IF(I9="","",IF(K9<>"",K9-I9,TODAY()-I9))
D10: =IF(OR(E10="",B10="完了"),"",IF(TODAY()>E10,"超過",IF(TODAY()+3>=E10,"間近",""))) | J10: =IF(I10="","",IF(K10<>"",K10-I10,TODAY()-I10))
D11: =IF(OR(E11="",B11="完了"),"",IF(TODAY()>E11,"超過",IF(TODAY()+3>=E11,"間近",""))) | J11: =IF(I11="","",IF(K11<>"",K11-I11,TODAY()-I11))
D12: =IF(OR(E12="",B12="完了"),"",IF(TODAY()>E12,"超過",IF(TODAY()+3>=E12,"間近",""))) | J12: =IF(I12="","",IF(K12<>"",K12-I12,TODAY()-I12))
D13: =IF(OR(E13="",B13="完了"),"",IF(TODAY()>E13,"超過",IF(TODAY()+3>=E13,"間近",""))) | J13: =IF(I13="","",IF(K13<>"",K13-I13,TODAY()-I13))
D14: =IF(OR(E14="",B14="完了"),"",IF(TODAY()>E14,"超過",IF(TODAY()+3>=E14,"間近",""))) | J14: =IF(I14="","",IF(K14<>"",K14-I14,TODAY()-I14))
D15: =IF(OR(E15="",B15="完了"),"",IF(TODAY()>E15,"超過",IF(TODAY()+3>=E15,"間近",""))) | J15: =IF(I15="","",IF(K15<>"",K15-I15,TODAY()-I15))
D16: =IF(OR(E16="",B16="完了"),"",IF(TODAY()>E16,"超過",IF(TODAY()+3>=E16,"間近",""))) | J16: =IF(I16="","",IF(K16<>"",K16-I16,TODAY()-I16))
D17: =IF(OR(E17="",B17="完了"),"",IF(TODAY()>E17,"超過",IF(TODAY()+3>=E17,"間近",""))) | J17: =IF(I17="","",IF(K17<>"",K17-I17,TODAY()-I17))
... D302: =IF(OR(E302="",B302="完了"),"",IF(TODAY()>E302,"超過",IF(TODAY()+3>=E302,"間近",""))) | J302: =IF(I302="","",IF(K302<>"",K302-I302,TODAY()-I302))

Sheet 集計
A1: 集計（自動計算・入力は不要です）
A2: 「対応管理表」シートの内容から自動で計算しています。集計日: | D2: =TODAY()
A4: ■ 対応状況別の件数 | D4: ■ 区分 × 対応状況
A5: 対応状況 | B5: 件数 | D5: 区分 | E5: 未対応 | F5: 対応中 | G5: 保留 | H5: 完了 | I5: 合計 | J5: 費用合計（円）
A6: 未対応 | B6: =COUNTIF('対応管理表'!$B$3:$B$1002,A6) | D6: 破損 | E6: =COUNTIFS('対応管理表'!$H$3:$H$1002,$D6,'対応管理表'!$B$3:$B$1002,E$5) | F6: =COUNTIFS('対応管理表'!$H$3:$H$1002,$D6,'対応管理表'!$B$3:$B$1002,F$5) | G6: =COUNTIFS('対応管理表'!$H$3:$H$1002,$D6,'対応管理表'!$B$3:$B$1002,G$5) | H6: =COUNTIFS('対応管理表'!$H$3:$H$1002,$D6,'対応管理表'!$B$3:$B$1002,H$5) | I6: =SUM(E6:H6) | J6: =SUMIF('対応管理表'!$H$3:$H$1002,$D6,'対応管理表'!$S$3:$S$1002)
A7: 対応中 | B7: =COUNTIF('対応管理表'!$B$3:$B$1002,A7) | D7: 故障 | E7: =COUNTIFS('対応管理表'!$H$3:$H$1002,$D7,'対応管理表'!$B$3:$B$1002,E$5) | F7: =COUNTIFS('対応管理表'!$H$3:$H$1002,$D7,'対応管理表'!$B$3:$B$1002,F$5) | G7: =COUNTIFS('対応管理表'!$H$3:$H$1002,$D7,'対応管理表'!$B$3:$B$1002,G$5) | H7: =COUNTIFS('対応管理表'!$H$3:$H$1002,$D7,'対応管理表'!$B$3:$B$1002,H$5) | I7: =SUM(E7:H7) | J7: =SUMIF('対応管理表'!$H$3:$H$1002,$D7,'対応管理表'!$S$3:$S$1002)
A8: 保留 | B8: =COUNTIF('対応管理表'!$B$3:$B$1002,A8) | D8: 盗難 | E8: =COUNTIFS('対応管理表'!$H$3:$H$1002,$D8,'対応管理表'!$B$3:$B$1002,E$5) | F8: =COUNTIFS('対応管理表'!$H$3:$H$1002,$D8,'対応管理表'!$B$3:$B$1002,F$5) | G8: =COUNTIFS('対応管理表'!$H$3:$H$1002,$D8,'対応管理表'!$B$3:$B$1002,G$5) | H8: =COUNTIFS('対応管理表'!$H$3:$H$1002,$D8,'対応管理表'!$B$3:$B$1002,H$5) | I8: =SUM(E8:H8) | J8: =SUMIF('対応管理表'!$H$3:$H$1002,$D8,'対応管理表'!$S$3:$S$1002)
A9: 完了 | B9: =COUNTIF('対応管理表'!$B$3:$B$1002,A9) | D9: 紛失 | E9: =COUNTIFS('対応管理表'!$H$3:$H$1002,$D9,'対応管理表'!$B$3:$B$1002,E$5) | F9: =COUNTIFS('対応管理表'!$H$3:$H$1002,$D9,'対応管理表'!$B$3:$B$1002,F$5) | G9: =COUNTIFS('対応管理表'!$H$3:$H$1002,$D9,'対応管理表'!$B$3:$B$1002,G$5) | H9: =COUNTIFS('対応管理表'!$H$3:$H$1002,$D9,'対応管理表'!$B$3:$B$1002,H$5) | I9: =SUM(E9:H9) | J9: =SUMIF('対応管理表'!$H$3:$H$1002,$D9,'対応管理表'!$S$3:$S$1002)
A10: 合計 | B10: =SUM(B6:B9) | D10: その他 | E10: =COUNTIFS('対応管理表'!$H$3:$H$1002,$D10,'対応管理表'!$B$3:$B$1002,E$5) | F10: =COUNTIFS('対応管理表'!$H$3:$H$1002,$D10,'対応管理表'!$B$3:$B$1002,F$5) | G10: =COUNTIFS('対応管理表'!$H$3:$H$1002,$D10,'対応管理表'!$B$3:$B$1002,G$5) | H10: =COUNTIFS('対応管理表'!$H$3:$H$1002,$D10,'対応管理表'!$B$3:$B$1002,H$5) | I10: =SUM(E10:H10) | J10: =SUMIF('対応管理表'!$H$3:$H$1002,$D10,'対応管理表'!$S$3:$S$1002)
A11: 未完了（未対応＋対応中＋保留） | B11: =B6+B7+B8 | D11: 合計 | E11: =SUM(E6:E10) | F11: =SUM(F6:F10) | G11: =SUM(G6:G10) | H11: =SUM(H6:H10) | I11: =SUM(I6:I10) | J11: =SUM(J6:J10)
A13: ■ 期限・その他
A14: 項目 | B14: 値
A15: 期限超過（未完了） | B15: =COUNTIF('対応管理表'!$D$3:$D$1002,"超過")
A16: 期限間近（3日以内） | B16: =COUNTIF('対応管理表'!$D$3:$D$1002,"間近")
A17: 今月の受付件数 | B17: =COUNTIFS('対応管理表'!$I$3:$I$1002,">="&DATE(YEAR(TODAY()),MONTH(TODAY()),1),'対応管理表'!$I$3:$I$1002,"<"&DATE(YEAR(TODAY()),MONTH(TODAY())+1,1))
A18: 費用合計（円） | B18: =SUM('対応管理表'!$S$3:$S$1002)

Sheet マスタ
A1: 区分 | B1: 対応状況 | C1: 優先度 | D1: 警察届出 | E1: 担当者 | G1: ■ このシートの使い方
A2: 破損 | B2: 未対応 | C2: 高 | D2: 不要 | E2: 総務 山田 | G2: 各列の選択肢が「対応管理表」シートのプルダウンに表示されます。
A3: 故障 | B3: 対応中 | C3: 中 | D3: 未 | E3: 総務 佐藤 | G3: 担当者（E列）は自社の担当者名に書き換えてください（20名まで登録できます）。
A4: 盗難 | B4: 保留 | C4: 低 | D4: 済 | E4: 総務 鈴木 | G4: 区分・対応状況の名前を変えた場合は、「集計」シートの項目名も同じ名前に揃えてください。
A5: 紛失 | B5: 完了
A6: その他

Sheet 使い方
B1: 対応管理表の使い方
C2: 備品・設備が壊れた／盗まれた／なくなった時に、「今どこまで対応が進んでいるか」を一覧で管理するための台帳です。
B4: 0. Google スプレッドシートへの取り込み（最初に1回だけ）
C5: ① drive.google.com を開き、このファイルを画面にドラッグ＆ドロップします。
C6: ② アップロードされたファイルを右クリック ＞ アプリで開く ＞ Google スプレッドシート。
C7: ③ ファイル ＞ Google スプレッドシートとして保存 を実行します。以降はこちらを使います。
C8: ④ 元のアップロードファイル（.xlsx）は削除して構いません。
C9: ※ プルダウン・色分け・自動計算はそのまま引き継がれます。Excel でそのまま使うこともできます。
B11: 1. 画面の見かた
B12: 1行目 | C12: 未完了・期限超過・期限間近・担当未定の件数がつねに表示されます。期限超過が1件でもあると赤字になります。右端に今日の日付と、次に使う管理No.が出ます。
B13: 固定表示 | C13: 1〜2行目と、管理No.・対応状況・対象物の3列は固定です。右にスクロールしても、どの案件の行かを見失いません。
B14: 1行1件 | C14: 文字を折り返さない設定にしているため、すべての行の高さが揃います。画面に多くの件数が並び、探しやすくなります。
B15: 長い文の読みかた | C15: 「状況・詳細」「対応内容・経過」は列の幅で切れて表示されます。全文はセルをクリックすると上の入力欄に出ます。ダブルクリックでも開けます。
B17: 2. 基本の流れ
C18: ① 報告を受けたら、一番下の空き行に1件1行で登録します。1行目の「次に使う管理No.」をそのまま管理No.欄に入力してください。
C19: ② 対象物・区分・受付日・発生場所・報告者・状況を埋めます。日付は Ctrl+; で今日の日付が入ります。
C20: ③ 対応担当者と対応期限を決め、対応状況を「未対応」から「対応中」に変えます。
C21: ④ 業者連絡や見積などの動きがあるたびに「対応内容・経過」の一番上に日付付きで追記します（セル内改行は Ctrl+Enter）。
C22: ⑤ 対応が終わったら対応状況を「完了」にし、完了日と費用を入力します。
C23: ※「対応内容・経過」は最新を一番上に書いてください。一覧には一番上の行だけが表示されるので、最新の動きが一目でわかります。
B25: 3. 色の意味（自動で付きます）
B26: 対応状況 | C26: 未対応＝赤、対応中＝黄、保留＝灰、完了＝緑。完了した行は文字全体が薄い灰色になります。
B27: 期限判定 | C27: 対応期限を過ぎた未完了案件は「超過」（赤地に白文字）になり、行全体が薄い赤になります。期限3日前からは「間近」（橙）です。
B28: 優先度 | C28: 「高」を選ぶと赤い太字になります。
B29: 灰色の見出しの列 | C29: 「期限判定」「経過日数」は自動計算です。入力しないでください。
B31: 4. 探す・絞り込む
B32: 今やるべき案件 | C32: 対応状況の見出しの絞り込みボタンから「完了」のチェックを外すと、未完了の案件だけが並びます。
B33: フィルタ表示 | C33: データ ＞ フィルタ表示 ＞ 新しいフィルタ表示を作成 を使うと、自分の画面だけで絞り込めます。通常の絞り込みは全員の画面に影響します。
B34: 並べ替え | C34: 対応期限の見出しの絞り込みボタンから「A→Z」で、期限が近い順に並びます。
B35: 検索 | C35: Ctrl+F で品名や報告者を検索できます。
B37: 5. 各列の説明
B38: 管理No. | C38: 案件の通し番号。1行目に出ている「次に使う管理No.」をそのまま入力してください（年-連番）。
B39: 対応状況 | C39: 未対応・対応中・保留・完了 から選びます。保留は、先方待ち・予算待ちなど自分では動かせない状態を指します。
B40: 対象物（品名） | C40: 何が壊れた／なくなったか。誰が見てもわかる呼び名で書きます。
B41: 対応期限 / 完了日 | C41: いつまでに対応するか、実際に終わった日。完了日を入れると経過日数が確定します。
B42: 優先度 | C42: 高＝業務停止や安全に関わる、中＝業務に支障あり、低＝急がない。
B43: 対応担当者 | C43: 「マスタ」シートの担当者リストから選びます。リストにない名前も直接入力できます。
B44: 区分 | C44: 破損・故障・盗難・紛失・その他 から選びます。
B45: 受付日 / 発生日 | C45: 受付日＝報告を受けた日、発生日＝実際に壊れた・盗まれた日。
B46: 発生場所 / 報告者 | C46: どこで起きたか、誰からの報告か（部署と氏名）。
...
