Workbook

Sheet 対応管理表
A1: 管理No. | B1: 受付日 | C1: 発生日 | D1: 区分 | E1: 対象物（品名） | F1: 資産番号 管理番号 | G1: 発生場所 | H1: 報告者 （部署・氏名） | I1: 状況・詳細 | J1: 優先度 | K1: 対応担当者 | L1: 対応状況 | M1: 対応内容・経過 | N1: 対応期限 | O1: 完了日 | P1: 経過日数 （自動） | Q1: 期限判定 （自動） | R1: 警察届出 （盗難・紛失時） | S1: 費用（円） | T1: 備考
A2: 2026-001 | B2: 46273 | C2: 46272 | D2: 破損 | E2: ノートPC（営業部貸与） | F2: PC-0123 | G2: 3F 営業部フロア | H2: 営業部 田中 | I2: 移動中に落下し、液晶画面が割れて表示できない。データは無事。 | J2: 高 | K2: 総務 山田 | L2: 対応中 | M2: 9/8 メーカーへ修理見積依頼 9/11 見積受領（45,000円）、上長承認 9/14 修理発注。納品予定が遅延中のため再確認 | N2: 46283 | P2: =IF(B2="","",IF(O2<>"",O2-B2,TODAY()-B2)) -> 12 | Q2: =IF(OR(N2="",L2="完了"),"",IF(TODAY()>N2,"超過",IF(TODAY()+3>=N2,"間近",""))) -> 超過 | R2: 不要 | S2: 45000 | T2: ※記入例（削除してOK）
A3: 2026-002 | B3: 46283 | C3: 46282 | D3: 盗難 | E3: 社用自転車 | F3: BK-002 | G3: 本社 駐輪場 | H3: 総務部 鈴木 | I3: 夜間に施錠して駐輪、翌朝出社時になくなっていた。防犯カメラ確認中。 | J3: 中 | K3: 総務 佐藤 | L3: 未対応 | M3: 9/18 上長へ報告済。警察への被害届は未提出。 | N3: 46287 | P3: =IF(B3="","",IF(O3<>"",O3-B3,TODAY()-B3)) -> 2 | Q3: =IF(OR(N3="",L3="完了"),"",IF(TODAY()>N3,"超過",IF(TODAY()+3>=N3,"間近",""))) -> 間近 | R3: 未 | T3: ※記入例（削除してOK）
A4: 2026-003 | B4: 46260 | C4: 46260 | D4: 故障 | E4: 複合機（2F コピーコーナー） | F4: MFP-02 | G4: 2F コピーコーナー | H4: 経理部 高橋 | I4: 紙詰まりが頻発し、エラー表示が消えない。 | J4: 中 | K4: 総務 山田 | L4: 完了 | M4: 8/26 保守業者へ連絡 8/28 訪問修理（給紙ローラー交換）、動作確認済 | N4: 46267 | O4: 46262 | P4: =IF(B4="","",IF(O4<>"",O4-B4,TODAY()-B4)) -> 2 | Q4: =IF(OR(N4="",L4="完了"),"",IF(TODAY()>N4,"超過",IF(TODAY()+3>=N4,"間近",""))) | R4: 不要 | S4: 0 | T4: ※記入例（削除してOK）保守契約内のため費用0円
P5: =IF(B5="","",IF(O5<>"",O5-B5,TODAY()-B5)) | Q5: =IF(OR(N5="",L5="完了"),"",IF(TODAY()>N5,"超過",IF(TODAY()+3>=N5,"間近","")))
P6: =IF(B6="","",IF(O6<>"",O6-B6,TODAY()-B6)) | Q6: =IF(OR(N6="",L6="完了"),"",IF(TODAY()>N6,"超過",IF(TODAY()+3>=N6,"間近","")))
P7: =IF(B7="","",IF(O7<>"",O7-B7,TODAY()-B7)) | Q7: =IF(OR(N7="",L7="完了"),"",IF(TODAY()>N7,"超過",IF(TODAY()+3>=N7,"間近","")))
P8: =IF(B8="","",IF(O8<>"",O8-B8,TODAY()-B8)) | Q8: =IF(OR(N8="",L8="完了"),"",IF(TODAY()>N8,"超過",IF(TODAY()+3>=N8,"間近","")))
P9: =IF(B9="","",IF(O9<>"",O9-B9,TODAY()-B9)) | Q9: =IF(OR(N9="",L9="完了"),"",IF(TODAY()>N9,"超過",IF(TODAY()+3>=N9,"間近","")))
P10: =IF(B10="","",IF(O10<>"",O10-B10,TODAY()-B10)) | Q10: =IF(OR(N10="",L10="完了"),"",IF(TODAY()>N10,"超過",IF(TODAY()+3>=N10,"間近","")))
P11: =IF(B11="","",IF(O11<>"",O11-B11,TODAY()-B11)) | Q11: =IF(OR(N11="",L11="完了"),"",IF(TODAY()>N11,"超過",IF(TODAY()+3>=N11,"間近","")))
P12: =IF(B12="","",IF(O12<>"",O12-B12,TODAY()-B12)) | Q12: =IF(OR(N12="",L12="完了"),"",IF(TODAY()>N12,"超過",IF(TODAY()+3>=N12,"間近","")))
P13: =IF(B13="","",IF(O13<>"",O13-B13,TODAY()-B13)) | Q13: =IF(OR(N13="",L13="完了"),"",IF(TODAY()>N13,"超過",IF(TODAY()+3>=N13,"間近","")))
P14: =IF(B14="","",IF(O14<>"",O14-B14,TODAY()-B14)) | Q14: =IF(OR(N14="",L14="完了"),"",IF(TODAY()>N14,"超過",IF(TODAY()+3>=N14,"間近","")))
P15: =IF(B15="","",IF(O15<>"",O15-B15,TODAY()-B15)) | Q15: =IF(OR(N15="",L15="完了"),"",IF(TODAY()>N15,"超過",IF(TODAY()+3>=N15,"間近","")))
P16: =IF(B16="","",IF(O16<>"",O16-B16,TODAY()-B16)) | Q16: =IF(OR(N16="",L16="完了"),"",IF(TODAY()>N16,"超過",IF(TODAY()+3>=N16,"間近","")))
... P300: =IF(B300="","",IF(O300<>"",O300-B300,TODAY()-B300)) | Q300: =IF(OR(N300="",L300="完了"),"",IF(TODAY()>N300,"超過",IF(TODAY()+3>=N300,"間近","")))

Sheet 集計
A1: 集計（自動計算・入力不要）
A2: 「対応管理表」シートの内容から自動で集計されます。集計日: | D2: =TODAY() -> 46285
A4: ■ 対応状況別の件数 | D4: ■ 区分 × 対応状況
A5: 対応状況 | B5: 件数 | D5: 区分 | E5: 未対応 | F5: 対応中 | G5: 保留 | H5: 完了 | I5: 合計 | J5: 費用合計（円）
A6: 未対応 | B6: =COUNTIF(対応管理表!$L$2:$L$1000,A6) -> 1 | D6: 破損 | E6: =COUNTIFS(対応管理表!$D$2:$D$1000,$D6,対応管理表!$L$2:$L$1000,E$5) -> 0 | F6: =COUNTIFS(対応管理表!$D$2:$D$1000,$D6,対応管理表!$L$2:$L$1000,F$5) -> 1 | G6: =COUNTIFS(対応管理表!$D$2:$D$1000,$D6,対応管理表!$L$2:$L$1000,G$5) -> 0 | H6: =COUNTIFS(対応管理表!$D$2:$D$1000,$D6,対応管理表!$L$2:$L$1000,H$5) -> 0 | I6: =SUM(E6:H6) -> 1 | J6: =SUMIF(対応管理表!$D$2:$D$1000,$D6,対応管理表!$S$2:$S$1000) -> 45000
A7: 対応中 | B7: =COUNTIF(対応管理表!$L$2:$L$1000,A7) -> 1 | D7: 故障 | E7: =COUNTIFS(対応管理表!$D$2:$D$1000,$D7,対応管理表!$L$2:$L$1000,E$5) -> 0 | F7: =COUNTIFS(対応管理表!$D$2:$D$1000,$D7,対応管理表!$L$2:$L$1000,F$5) -> 0 | G7: =COUNTIFS(対応管理表!$D$2:$D$1000,$D7,対応管理表!$L$2:$L$1000,G$5) -> 0 | H7: =COUNTIFS(対応管理表!$D$2:$D$1000,$D7,対応管理表!$L$2:$L$1000,H$5) -> 1 | I7: =SUM(E7:H7) -> 1 | J7: =SUMIF(対応管理表!$D$2:$D$1000,$D7,対応管理表!$S$2:$S$1000) -> 0
A8: 保留 | B8: =COUNTIF(対応管理表!$L$2:$L$1000,A8) -> 0 | D8: 盗難 | E8: =COUNTIFS(対応管理表!$D$2:$D$1000,$D8,対応管理表!$L$2:$L$1000,E$5) -> 1 | F8: =COUNTIFS(対応管理表!$D$2:$D$1000,$D8,対応管理表!$L$2:$L$1000,F$5) -> 0 | G8: =COUNTIFS(対応管理表!$D$2:$D$1000,$D8,対応管理表!$L$2:$L$1000,G$5) -> 0 | H8: =COUNTIFS(対応管理表!$D$2:$D$1000,$D8,対応管理表!$L$2:$L$1000,H$5) -> 0 | I8: =SUM(E8:H8) -> 1 | J8: =SUMIF(対応管理表!$D$2:$D$1000,$D8,対応管理表!$S$2:$S$1000) -> 0
A9: 完了 | B9: =COUNTIF(対応管理表!$L$2:$L$1000,A9) -> 1 | D9: 紛失 | E9: =COUNTIFS(対応管理表!$D$2:$D$1000,$D9,対応管理表!$L$2:$L$1000,E$5) -> 0 | F9: =COUNTIFS(対応管理表!$D$2:$D$1000,$D9,対応管理表!$L$2:$L$1000,F$5) -> 0 | G9: =COUNTIFS(対応管理表!$D$2:$D$1000,$D9,対応管理表!$L$2:$L$1000,G$5) -> 0 | H9: =COUNTIFS(対応管理表!$D$2:$D$1000,$D9,対応管理表!$L$2:$L$1000,H$5) -> 0 | I9: =SUM(E9:H9) -> 0 | J9: =SUMIF(対応管理表!$D$2:$D$1000,$D9,対応管理表!$S$2:$S$1000) -> 0
A10: 合計 | B10: =SUM(B6:B9) -> 3 | D10: その他 | E10: =COUNTIFS(対応管理表!$D$2:$D$1000,$D10,対応管理表!$L$2:$L$1000,E$5) -> 0 | F10: =COUNTIFS(対応管理表!$D$2:$D$1000,$D10,対応管理表!$L$2:$L$1000,F$5) -> 0 | G10: =COUNTIFS(対応管理表!$D$2:$D$1000,$D10,対応管理表!$L$2:$L$1000,G$5) -> 0 | H10: =COUNTIFS(対応管理表!$D$2:$D$1000,$D10,対応管理表!$L$2:$L$1000,H$5) -> 0 | I10: =SUM(E10:H10) -> 0 | J10: =SUMIF(対応管理表!$D$2:$D$1000,$D10,対応管理表!$S$2:$S$1000) -> 0
A11: 未完了（未対応＋対応中＋保留） | B11: =B6+B7+B8 -> 2 | D11: 合計 | E11: =SUM(E6:E10) -> 1 | F11: =SUM(F6:F10) -> 1 | G11: =SUM(G6:G10) -> 0 | H11: =SUM(H6:H10) -> 1 | I11: =SUM(I6:I10) -> 3 | J11: =SUM(J6:J10) -> 45000
A13: ■ 期限・その他
A14: 項目 | B14: 値
A15: 期限超過（未完了） | B15: =COUNTIF(対応管理表!$Q$2:$Q$1000,"超過") -> 1
A16: 期限間近（3日以内） | B16: =COUNTIF(対応管理表!$Q$2:$Q$1000,"間近") -> 1
A17: 今月の受付件数 | B17: =COUNTIFS(対応管理表!$B$2:$B$1000,">="&DATE(YEAR(TODAY()),MONTH(TODAY()),1),対応管理表!$B$2:$B$1000,"<"&DATE(YEAR(TODAY()),MONTH(TODAY())+1,1)) -> 2
A18: 費用合計（円） | B18: =SUM(対応管理表!$S$2:$S$1000) -> 45000

Sheet マスタ
A1: 区分 | B1: 対応状況 | C1: 優先度 | D1: 警察届出 | E1: 担当者 | G1: ■ このシートの使い方
A2: 破損 | B2: 未対応 | C2: 高 | D2: 不要 | E2: 総務 山田 | G2: 各列の選択肢が「対応管理表」シートのプルダウンに表示されます。
A3: 故障 | B3: 対応中 | C3: 中 | D3: 未 | E3: 総務 佐藤 | G3: 担当者（E列）は自社の担当者名に書き換えてください（20名まで登録可）。
A4: 盗難 | B4: 保留 | C4: 低 | D4: 済 | E4: 総務 鈴木 | G4: 区分・対応状況の選択肢を変える場合は、「集計」シートの項目名も合わせて変更してください。
A5: 紛失 | B5: 完了
A6: その他

Sheet 使い方
B1: 対応管理表の使い方
C2: 備品・設備が壊れた／盗まれた／なくなった時に、「今どこまで対応が進んでいるか」を一覧で管理するための台帳です。
B4: 0. Google スプレッドシートへの取り込み（最初に1回だけ）
C5: ① drive.google.com を開き、このファイルをブラウザ画面にドラッグ＆ドロップする（または「新規」＞「ファイルのアップロード」）。
C6: ② アップロードされたファイルを右クリック ＞ アプリで開く ＞ Google スプレッドシート。
C7: ③ 開いたら ファイル ＞ Google スプレッドシートとして保存 を実行する（以降はこちらを使います）。
C8: ④ 元のアップロードファイル（.xlsx）は不要になるので削除して構いません。
C9: ※ プルダウン・色分け・自動計算はそのまま引き継がれます。
B11: 1. 基本の流れ
C12: ① 報告を受けたら「対応管理表」シートの一番下の空き行に1件1行で登録する（管理No.・受付日・区分・対象物・報告者・状況）。
C13: ② 対応担当者と対応期限を決め、対応状況を「未対応」→「対応中」に変える。
C14: ③ 業者連絡や見積などの動きがあるたびに「対応内容・経過」に日付付きで追記する（セル内改行は Ctrl+Enter）。
C15: ④ 対応が終わったら対応状況を「完了」にし、完了日と費用を記入する。
C16: ⑤ 朝礼・定例などでは「集計」シートで未完了件数と期限超過件数を確認する。
B18: 2. 色の意味（自動で色が付きます）
B19: 対応状況 | C19: 未対応＝赤、対応中＝黄、保留＝灰、完了＝緑。完了した行は文字が灰色になります。
B20: 期限判定 | C20: 対応期限を過ぎた未完了案件は「超過」（赤）となり行全体が薄い赤に、期限3日前からは「間近」（橙）になります。
B21: 灰色の列 | C21: 「経過日数」「期限判定」は自動計算です。入力しないでください。
B23: 3. 各列の説明
B24: 管理No. | C24: 案件の通し番号。「2026-001」のように 年-連番 で付けると探しやすいです（手入力）。
B25: 受付日 / 発生日 | C25: 受付日＝報告を受けた日、発生日＝実際に壊れた・盗まれた日。
B26: 区分 | C26: 破損・故障・盗難・紛失・その他 から選択。
B27: 対象物 / 資産番号 | C27: 何が対象か。備品シールや資産台帳の番号があれば資産番号に記入。
B28: 発生場所 / 報告者 | C28: どこで起きたか、誰からの報告か（部署と氏名）。
B29: 状況・詳細 | C29: 報告時点でわかっている事実を記入。原因の推測と事実は分けて書くと後で役立ちます。
B30: 優先度 | C30: 高＝業務停止・安全に関わる、中＝業務に支障あり、低＝急がない。
B31: 対応担当者 | C31: 「マスタ」シートの担当者リストから選択（リストにない名前も直接入力できます）。
B32: 対応状況 | C32: 未対応・対応中・保留・完了 から選択。保留＝先方待ち・予算待ちなど自分では動けない状態。
B33: 対応内容・経過 | C33: 「9/5 見積受領」のように日付付きで時系列に追記。最新の状況が上か下か、部署内でルールを決めてください。
B34: 対応期限 / 完了日 | C34: いつまでに対応するか／実際に完了した日。完了日を入れると経過日数が確定します。
B35: 警察届出 | C35: 盗難・紛失の場合は必ず記入（不要・未・済）。被害届の受理番号は備考へ。
B36: 費用（円） | C36: 修理費・買替費など。見積段階でも見込額を入れておくと集計に反映されます。
B38: 4. 複数人で使うときのコツ（スプレッドシートならでは）
B39: 共有 | C39: 右上の「共有」から同僚を追加します。編集してほしい人は「編集者」、見るだけの人は「閲覧者」にします。
B40: 同時編集 | C40: 全員が同時に開いて編集できます。編集中のセルには相手の色枠と名前が出るので、同じ行を触らないようにしてください。
B41: フィルタ表示 | C41: データ ＞ フィルタ表示 ＞ 新しいフィルタ表示を作成 を使うと、自分の画面だけで絞り込めます。通常のフィルタは全員の画面に影響します。
B42: 担当者への通知 | C42: セルを右クリック ＞ コメント で「@メールアドレス」と書くと、担当者にメールで通知が届きます。依頼や催促に便利です。
B43: 変更履歴 | C43: ファイル ＞ 変更履歴 ＞ 変更履歴を表示 で、誰がいつ何を書き換えたか確認できます。消してしまった内容も戻せます。
B44: スマホ | C44: Google スプレッドシートのアプリを入れておくと、現場で写真を撮った直後にスマホから登録できます。
B46: 5. 注意点
...
